Workbook

Sheet Darajalar
A3: Blue Wolf — oʻyinchi darajalari (1–25)
A4: Eng zaifdan eng kuchligacha. Koʻk raqamlar — qoʻlda sozlanadigan modifikatorlar.
A5: Daraja | B5: Boʻri nomi | C5: Ilmiy / afsonaviy nom | D5: Toifa | E5: Vazni (kg) | F5: Toifa koeff. | G5: Kuch mod. | H5: Tezlik mod. | I5: Daraja narxi (XP) | J5: Jami XP | K5: Kuch | L5: Tezlik | M5: Chidam (HP) | N5: Jangovar quvvat | O5: Toʻda hajmi | P5: Bosqich koeff. | Q5: Ochiladigan imkoniyat
A6: 1 | B6: Honsyu boʻrisi | C6: Canis lupus hodophilax | D6: Haqiqiy | E6: 15 | F6: =IF(D6="Haqiqiy",class_real,IF(D6="Qadimgi",class_ancient,class_myth)) -> 1 | G6: 0.9 | H6: 1.1 | I6: 0 | J6: 0 | K6: =ROUND(stat_power_base*stat_power_growth^(A6-1)*F6*G6,0) -> 11 | L6: =ROUND(stat_speed_base*stat_speed_growth^(A6-1)*F6*H6,0) -> 11 | M6: =ROUND(stat_hp_base*stat_hp_growth^(A6-1)*F6,0) -> 60 | N6: =ROUND(K6*cp_w_power+L6*cp_w_speed+M6*cp_w_hp,0) -> 69 | O6: =IF(A6<pack_unlock_level,pack_solo_size,ROUND(pack_base*pack_growth^(A6-pack_unlock_level),0)) -> 1 | P6: =IF(A6<=4,stage_early,IF(A6<=stage_mid_level,stage_mid,IF(A6<=stage_late_level,stage_normal,stage_late))) -> 0.4 | Q6: Yolgʻiz ov (alfa): kemiruvchi va qush; In
A7: 2 | B7: Efiopiya boʻrisi | C7: Canis simensis | D7: Haqiqiy | E7: 16 | F7: =IF(D7="Haqiqiy",class_real,IF(D7="Qadimgi",class_ancient,class_myth)) -> 1 | G7: 0.92 | H7: 1.12 | I7: =ROUND(xp_base*xp_growth^(A7-2)*P7,-1) -> 30 | J7: =J6+I7 -> 30 | K7: =ROUND(stat_power_base*stat_power_growth^(A7-1)*F7*G7,0) -> 13 | L7: =ROUND(stat_speed_base*stat_speed_growth^(A7-1)*F7*H7,0) -> 13 | M7: =ROUND(stat_hp_base*stat_hp_growth^(A7-1)*F7,0) -> 71 | N7: =ROUND(K7*cp_w_power+L7*cp_w_speed+M7*cp_w_hp,0) -> 81 | O7: =IF(A7<pack_unlock_level,pack_solo_size,ROUND(pack_base*pack_growth^(A7-pack_unlock_level),0)) -> 1 | P7: =IF(A7<=4,stage_early,IF(A7<=stage_mid_level,stage_mid,IF(A7<=stage_late_level,stage_normal,stage_late))) -> 0.4 | Q7: Oziq gʻori va Ustaxona qoyasi
A8: 3 | B8: Arab boʻrisi | C8: Canis lupus arabs | D8: Haqiqiy | E8: 20 | F8: =IF(D8="Haqiqiy",class_real,IF(D8="Qadimgi",class_ancient,class_myth)) -> 1 | G8: 0.95 | H8: 1.15 | I8: =ROUND(xp_base*xp_growth^(A8-2)*P8,-1) -> 40 | J8: =J7+I8 -> 70 | K8: =ROUND(stat_power_base*stat_power_growth^(A8-1)*F8*G8,0) -> 16 | L8: =ROUND(stat_speed_base*stat_speed_growth^(A8-1)*F8*H8,0) -> 15 | M8: =ROUND(stat_hp_base*stat_hp_growth^(A8-1)*F8,0) -> 84 | N8: =ROUND(K8*cp_w_power+L8*cp_w_speed+M8*cp_w_hp,0) -> 97 | O8: =IF(A8<pack_unlock_level,pack_solo_size,ROUND(pack_base*pack_growth^(A8-pack_unlock_level),0)) -> 1 | P8: =IF(A8<=4,stage_early,IF(A8<=stage_mid_level,stage_mid,IF(A8<=stage_late_level,stage_normal,stage_late))) -> 0.4 | Q8: Ov soʻqmogʻi, birinchi ovchi, quyon ovi
A9: 4 | B9: Hind boʻrisi | C9: Canis lupus pallipes | D9: Haqiqiy | E9: 25 | F9: =IF(D9="Haqiqiy",class_real,IF(D9="Qadimgi",class_ancient,class_myth)) -> 1 | G9: 0.98 | H9: 1.14 | I9: =ROUND(xp_base*xp_growth^(A9-2)*P9,-1) -> 60 | J9: =J8+I9 -> 130 | K9: =ROUND(stat_power_base*stat_power_growth^(A9-1)*F9*G9,0) -> 20 | L9: =ROUND(stat_speed_base*stat_speed_growth^(A9-1)*F9*H9,0) -> 16 | M9: =ROUND(stat_hp_base*stat_hp_growth^(A9-1)*F9,0) -> 99 | N9: =ROUND(K9*cp_w_power+L9*cp_w_speed+M9*cp_w_hp,0) -> 114 | O9: =IF(A9<pack_unlock_level,pack_solo_size,ROUND(pack_base*pack_growth^(A9-pack_unlock_level),0)) -> 10 | P9: =IF(A9<=4,stage_early,IF(A9<=stage_mid_level,stage_mid,IF(A9<=stage_late_level,stage_normal,stage_late))) -> 0.4 | Q9: 🔓 TOʻDA: qoʻshin 10 askar · Jang maydoni, Razvedka qoyasi, Himoya devori · yovvoyi toʻdalarga (bot) hujum · ov guruhi · klan va lager (v2)
A10: 5 | B10: Qizil boʻri | C10: Canis rufus | D10: Haqiqiy | E10: 30 | F10: =IF(D10="Haqiqiy",class_real,IF(D10="Qadimgi",class_ancient,class_myth)) -> 1 | G10: 1 | H10: 1.08 | I10: =ROUND(xp_base*xp_growth^(A10-2)*P10,-1) -> 150 | J10: =J9+I10 -> 280 | K10: =ROUND(stat_power_base*stat_power_growth^(A10-1)*F10*G10,0) -> 25 | L10: =ROUND(stat_speed_base*stat_speed_growth^(A10-1)*F10*H10,0) -> 18 | M10: =ROUND(stat_hp_base*stat_hp_growth^(A10-1)*F10,0) -> 116 | N10: =ROUND(K10*cp_w_power+L10*cp_w_speed+M10*cp_w_hp,0) -> 135 | O10: =IF(A10<pack_unlock_level,pack_solo_size,ROUND(pack_base*pack_growth^(A10-pack_unlock_level),0)) -> 12 | P10: =IF(A10<=4,stage_early,IF(A10<=stage_mid_level,stage_mid,IF(A10<=stage_late_level,stage_normal,stage_late))) -> 0.7 | Q10: Yirik oʻlja — jayron (kamida 2 boʻri)
A11: 6 | B11: Italyan boʻrisi | C11: Canis lupus italicus | D11: Haqiqiy | E11: 32 | F11: =IF(D11="Haqiqiy",class_real,IF(D11="Qadimgi",class_ancient,class_myth)) -> 1 | G11: 1.02 | H11: 1.06 | I11: =ROUND(xp_base*xp_growth^(A11-2)*P11,-1) -> 200 | J11: =J10+I11 -> 480 | K11: =ROUND(stat_power_base*stat_power_growth^(A11-1)*F11*G11,0) -> 30 | L11: =ROUND(stat_speed_base*stat_speed_growth^(A11-1)*F11*H11,0) -> 20 | M11: =ROUND(stat_hp_base*stat_hp_growth^(A11-1)*F11,0) -> 137 | N11: =ROUND(K11*cp_w_power+L11*cp_w_speed+M11*cp_w_hp,0) -> 159 | O11: =IF(A11<pack_unlock_level,pack_solo_size,ROUND(pack_base*pack_growth^(A11-pack_unlock_level),0)) -> 14 | P11: =IF(A11<=4,stage_early,IF(A11<=stage_mid_level,stage_mid,IF(A11<=stage_late_level,stage_normal,stage_late))) -> 0.7 | Q11: 🏥 Shifo gʻori · suv oazisi (v2)
A12: 7 | B12: Meksika boʻrisi | C12: Canis lupus baileyi | D12: Haqiqiy | E12: 33 | F12: =IF(D12="Haqiqiy",class_real,IF(D12="Qadimgi",class_ancient,class_myth)) -> 1 | G12: 1.03 | H12: 1.07 | I12: =ROUND(xp_base*xp_growth^(A12-2)*P12,-1) -> 280 | J12: =J11+I12 -> 760 | K12: =ROUND(stat_power_base*stat_power_growth^(A12-1)*F12*G12,0) -> 37 | L12: =ROUND(stat_speed_base*stat_speed_growth^(A12-1)*F12*H12,0) -> 22 | M12: =ROUND(stat_hp_base*stat_hp_growth^(A12-1)*F12,0) -> 162 | N12: =ROUND(K12*cp_w_power+L12*cp_w_speed+M12*cp_w_hp,0) -> 188 | O12: =IF(A12<pack_unlock_level,pack_solo_size,ROUND(pack_base*pack_growth^(A12-pack_unlock_level),0)) -> 17 | P12: =IF(A12<=4,stage_early,IF(A12<=stage_mid_level,stage_mid,IF(A12<=stage_late_level,stage_normal,stage_late))) -> 0.7 | Q12: 🔓 Haqiqiy oʻyinchilarga hujum (qalqon tugaydi) · reyting va liga (v2)
A13: 8 | B13: Sharqiy boʻri | C13: Canis lycaon | D13: Haqiqiy | E13: 35 | F13: =IF(D13="Haqiqiy",class_real,IF(D13="Qadimgi",class_ancient,class_myth)) -> 1 | G13: 1.04 | H13: 1.05 | I13: =ROUND(xp_base*xp_growth^(A13-2)*P13,-1) -> 390 | J13: =J12+I13 -> 1150 | K13: =ROUND(stat_power_base*stat_power_growth^(A13-1)*F13*G13,0) -> 45 | L13: =ROUND(stat_speed_base*stat_speed_growth^(A13-1)*F13*H13,0) -> 25 | M13: =ROUND(stat_hp_base*stat_hp_growth^(A13-1)*F13,0) -> 191 | N13: =ROUND(K13*cp_w_power+L13*cp_w_speed+M13*cp_w_hp,0) -> 223 | O13: =IF(A13<pack_unlock_level,pack_solo_size,ROUND(pack_base*pack_growth^(A13-pack_unlock_level),0)) -> 21 | P13: =IF(A13<=4,stage_early,IF(A13<=stage_mid_level,stage_mid,IF(A13<=stage_late_level,stage_normal,stage_late))) -> 0.7 | Q13: Toʻda urushi (v2) · oʻt oazisi (v2)
A14: 9 | B14: Iberiya boʻrisi | C14: Canis lupus signatus | D14: Haqiqiy | E14: 38 | F14: =IF(D14="Haqiqiy",class_real,IF(D14="Qadimgi",class_ancient,class_myth)) -> 1 | G14: 1.06 | H14: 1.03 | I14: =ROUND(xp_base*xp_growth^(A14-2)*P14,-1) -> 530 | J14: =J13+I14 -> 1680 | K14: =ROUND(stat_power_base*stat_power_growth^(A14-1)*F14*G14,0) -> 55 | L14: =ROUND(stat_speed_base*stat_speed_growth^(A14-1)*F14*H14,0) -> 27 | M14: =ROUND(stat_hp_base*stat_hp_growth^(A14-1)*F14,0) -> 226 | N14: =ROUND(K14*cp_w_power+L14*cp_w_speed+M14*cp_w_hp,0) -> 264 | O14: =IF(A14<pack_unlock_level,pack_solo_size,ROUND(pack_base*pack_growth^(A14-pack_unlock_level),0)) -> 25 | P14: =IF(A14<=4,stage_early,IF(A14<=stage_mid_level,stage_mid,IF(A14<=stage_late_level,stage_normal,stage_late))) -> 0.7 | Q14: 🛒 Bozor · toʻda lavozimlari (v2)
A15: 10 | B15: Dasht boʻrisi | C15: Canis lupus campestris | D15: Haqiqiy | E15: 40 | F15: =IF(D15="Haqiqiy",class_real,IF(D15="Qadimgi",class_ancient,class_myth)) -> 1 | G15: 1.07 | H15: 1.1 | I15: =ROUND(xp_base*xp_growth^(A15-2)*P15,-1) -> 740 | J15: =J14+I15 -> 2420 | K15: =ROUND(stat_power_base*stat_power_growth^(A15-1)*F15*G15,0) -> 66 | L15: =ROUND(stat_speed_base*stat_speed_growth^(A15-1)*F15*H15,0) -> 33 | M15: =ROUND(stat_hp_base*stat_hp_growth^(A15-1)*F15,0) -> 266 | N15: =ROUND(K15*cp_w_power+L15*cp_w_speed+M15*cp_w_hp,0) -> 315 | O15: =IF(A15<pack_unlock_level,pack_solo_size,ROUND(pack_base*pack_growth^(A15-pack_unlock_level),0)) -> 30 | P15: =IF(A15<=4,stage_early,IF(A15<=stage_mid_level,stage_mid,IF(A15<=stage_late_level,stage_normal,stage_late))) -> 0.7 | Q15: Ikkinchi qurilish navbati — hammaga bepul
A16: 11 | B16: Himolay boʻrisi | C16: Canis lupus chanco | D16: Haqiqiy | E16: 42 | F16: =IF(D16="Haqiqiy",class_real,IF(D16="Qadimgi",class_ancient,class_myth)) -> 1 | G16: 1.09 | H16: 1.02 | I16: =ROUND(xp_base*xp_growth^(A16-2)*P16,-1) -> 1450 | J16: =J15+I16 -> 3870 | K16: =ROUND(stat_power_base*stat_power_growth^(A16-1)*F16*G16,0) -> 81 | L16: =ROUND(stat_speed_base*stat_speed_growth^(A16-1)*F16*H16,0) -> 35 | M16: =ROUND(stat_hp_base*stat_hp_growth^(A16-1)*F16,0) -> 314 | N16: =ROUND(K16*cp_w_power+L16*cp_w_speed+M16*cp_w_hp,0) -> 372 | O16: =IF(A16<pack_unlock_level,pack_solo_size,ROUND(pack_base*pack_growth^(A16-pack_unlock_level),0)) -> 36 | P16: =IF(A16<=4,stage_early,IF(A16<=stage_mid_level,stage_mid,IF(A16<=stage_late_level,stage_normal,stage_late))) -> 1 | Q16: Co-op boss: togʻ ayigʻi (v3)
A17: 12 | B17: Ezo boʻrisi | C17: Canis lupus hattai | D17: Haqiqiy | E17: 44 | F17: =IF(D17="Haqiqiy",class_real,IF(D17="Qadimgi",class_ancient,class_myth)) -> 1 | G17: 1.1 | H17: 1.01 | I17: =ROUND(xp_base*xp_growth^(A17-2)*P17,-1) -> 2000 | J17: =J16+I17 -> 5870 | K17: =ROUND(stat_power_base*stat_power_growth^(A17-1)*F17*G17,0) -> 98 | L17: =ROUND(stat_speed_base*stat_speed_growth^(A17-1)*F17*H17,0) -> 39 | M17: =ROUND(stat_hp_base*stat_hp_growth^(A17-1)*F17,0) -> 371 | N17: =ROUND(K17*cp_w_power+L17*cp_w_speed+M17*cp_w_hp,0) -> 440 | O17: =IF(A17<pack_unlock_level,pack_solo_size,ROUND(pack_base*pack_growth^(A17-pack_unlock_level),0)) -> 43 | P17: =IF(A17<=4,stage_early,IF(A17<=stage_mid_level,stage_mid,IF(A17<=stage_late_level,stage_normal,stage_late))) -> 1 | Q17: Toʻda xazinasi (v2) · tosh koni (v2)
A18: 13 | B18: Tibet boʻrisi | C18: Canis lupus filchneri | D18: Haqiqiy | E18: 45 | F18: =IF(D18="Haqiqiy",class_real,IF(D18="Qadimgi",class_ancient,class_myth)) -> 1 | G18: 1.11 | H18: 1 | I18: =ROUND(xp_base*xp_growth^(A18-2)*P18,-1) -> 2770 | J18: =J17+I18 -> 8640 | K18: =ROUND(stat_power_base*stat_power_growth^(A18-1)*F18*G18,0) -> 119 | L18: =ROUND(stat_speed_base*stat_speed_growth^(A18-1)*F18*H18,0) -> 43 | M18: =ROUND(stat_hp_base*stat_hp_growth^(A18-1)*F18,0) -> 437 | N18: =ROUND(K18*cp_w_power+L18*cp_w_speed+M18*cp_w_hp,0) -> 521 | O18: =IF(A18<pack_unlock_level,pack_solo_size,ROUND(pack_base*pack_growth^(A18-pack_unlock_level),0)) -> 52 | P18: =IF(A18<=4,stage_early,IF(A18<=stage_mid_level,stage_mid,IF(A18<=stage_late_level,stage_normal,stage_late))) -> 1 | Q18: Himoya urushi (v3)
... A26: 21 | B26: Dahshatli boʻri | C26: Aenocyon dirus | D26: Qadimgi | E26: 70 | F26: =IF(D26="Haqiqiy",class_real,IF(D26="Qadimgi",class_ancient,class_myth)) -> 1.35 | G26: 1.4 | H26: 0.9 | I26: =ROUND(xp_base*xp_growth^(A26-2)*P26,-1) -> 45470 | J26: =J25+I26 -> 158950 | K26: =ROUND(stat_power_base*stat_power_growth^(A26-1)*F26*G26,0) -> 869 | L26: =ROUND(stat_speed_base*stat_speed_growth^(A26-1)*F26*H26,0) -> 140 | M26: =ROUND(stat_hp_base*stat_hp_growth^(A26-1)*F26,0) -> 2219 | N26: =ROUND(K26*cp_w_power+L26*cp_w_speed+M26*cp_w_hp,0) -> 3058 | O26: =IF(A26<pack_unlock_level,pack_solo_size,ROUND(pack_base*pack_growth^(A26-pack_unlock_level),0)) -> 222 | P26: =IF(A26<=4,stage_early,IF(A26<=stage_mid_level,stage_mid,IF(A26<=stage_late_level,stage_normal,stage_late))) -> 1.25 | Q26: Afsona bossi (v3)
A27: 22 | B27: Amarok | C27: Inuit afsonasi | D27: Mifologik | F27: =IF(D27="Haqiqiy",class_real,IF(D27="Qadimgi",class_ancient,class_myth)) -> 1.8 | G27: 1.5 | H27: 1 | I27: =ROUND(xp_base*xp_growth^(A27-2)*P27,-1) -> 62750 | J27: =J26+I27 -> 221700 | K27: =ROUND(stat_power_base*stat_power_growth^(A27-1)*F27*G27,0) -> 1491 | L27: =ROUND(stat_speed_base*stat_speed_growth^(A27-1)*F27*H27,0) -> 234 | M27: =ROUND(stat_hp_base*stat_hp_growth^(A27-1)*F27,0) -> 3491 | N27: =ROUND(K27*cp_w_power+L27*cp_w_speed+M27*cp_w_hp,0) -> 5079 | O27: =IF(A27<pack_unlock_level,pack_solo_size,ROUND(pack_base*pack_growth^(A27-pack_unlock_level),0)) -> 266 | P27: =IF(A27<=4,stage_early,IF(A27<=stage_mid_level,stage_mid,IF(A27<=stage_late_level,stage_normal,stage_late))) -> 1.25 | Q27: Tungi reyd: 22:00–06:00 yurish tezligi +25%
A28: 23 | B28: Geri va Freki | C28: Skandinaviya afsonasi | D28: Mifologik | F28: =IF(D28="Haqiqiy",class_real,IF(D28="Qadimgi",class_ancient,class_myth)) -> 1.8 | G28: 1.6 | H28: 1.1 | I28: =ROUND(xp_base*xp_growth^(A28-2)*P28,-1) -> 86590 | J28: =J27+I28 -> 308290 | K28: =ROUND(stat_power_base*stat_power_growth^(A28-1)*F28*G28,0) -> 1908 | L28: =ROUND(stat_speed_base*stat_speed_growth^(A28-1)*F28*H28,0) -> 291 | M28: =ROUND(stat_hp_base*stat_hp_growth^(A28-1)*F28,0) -> 4119 | N28: =ROUND(K28*cp_w_power+L28*cp_w_speed+M28*cp_w_hp,0) -> 6312 | O28: =IF(A28<pack_unlock_level,pack_solo_size,ROUND(pack_base*pack_growth^(A28-pack_unlock_level),0)) -> 319 | P28: =IF(A28<=4,stage_early,IF(A28<=stage_mid_level,stage_mid,IF(A28<=stage_late_level,stage_normal,stage_late))) -> 1.25 | Q28: Juft hujum (v3)
A29: 24 | B29: Fenrir | C29: Skandinaviya afsonasi | D29: Mifologik | F29: =IF(D29="Haqiqiy",class_real,IF(D29="Qadimgi",class_ancient,class_myth)) -> 1.8 | G29: 1.8 | H29: 0.95 | I29: =ROUND(xp_base*xp_growth^(A29-2)*P29,-1) -> 119490 | J29: =J28+I29 -> 427780 | K29: =ROUND(stat_power_base*stat_power_growth^(A29-1)*F29*G29,0) -> 2576 | L29: =ROUND(stat_speed_base*stat_speed_growth^(A29-1)*F29*H29,0) -> 284 | M29: =ROUND(stat_hp_base*stat_hp_growth^(A29-1)*F29,0) -> 4861 | N29: =ROUND(K29*cp_w_power+L29*cp_w_speed+M29*cp_w_hp,0) -> 8009 | O29: =IF(A29<pack_unlock_level,pack_solo_size,ROUND(pack_base*pack_growth^(A29-pack_unlock_level),0)) -> 383 | P29: =IF(A29<=4,stage_early,IF(A29<=stage_mid_level,stage_mid,IF(A29<=stage_late_level,stage_normal,stage_late))) -> 1.25 | Q29: Zanjirni uzish: urushdan keyin jarohatlanganlar 2× tez davolanadi
A30: 25 | B30: Koʻk Boʻri | C30: Koʻkboʻri / Boʻrte Chino | D30: Mifologik | F30: =IF(D30="Haqiqiy",class_real,IF(D30="Qadimgi",class_ancient,class_myth)) -> 1.8 | G30: 2 | H30: 1.05 | I30: =ROUND(xp_base*xp_growth^(A30-2)*P30,-1) -> 164900 | J30: =J29+I30 -> 592680 | K30: =ROUND(stat_power_base*stat_power_growth^(A30-1)*F30*G30,0) -> 3434 | L30: =ROUND(stat_speed_base*stat_speed_growth^(A30-1)*F30*H30,0) -> 355 | M30: =ROUND(stat_hp_base*stat_hp_growth^(A30-1)*F30,0) -> 5736 | N30: =ROUND(K30*cp_w_power+L30*cp_w_speed+M30*cp_w_hp,0) -> 10269 | O30: =IF(A30<pack_unlock_level,pack_solo_size,ROUND(pack_base*pack_growth^(A30-pack_unlock_level),0)) -> 460 | P30: =IF(A30<=4,stage_early,IF(A30<=stage_mid_level,stage_mid,IF(A30<=stage_late_level,stage_normal,stage_late))) -> 1.25 | Q30: Koʻk Boʻri unvoni · klanga +10% ishlab chiqarish (kuch emas)
B31: JAMI (1→25 darajagacha kerakli XP) | J31: =J30 -> 592680
A32: Formulalar: Daraja narxi = ROUND(Bazaviy XP × XP oʻsishi^(daraja−2) × bosqich koeff., −1) · Kuch = Bazaviy kuch × Kuch oʻsishi^(daraja−1) × Toifa koeff. × Kuch mod. Barcha koeffitsientlar Sozlamalar varagʻidan (nomlangan kataklar).
A33: Jangovar quvvat (CP) = Kuch×2 + Tezlik×1.5 + Chidam×0.5 — matchmaking va reyting uchun shu raqamdan foydalaning.
A34: Kuch mod. va Tezlik mod. — har bir boʻrining xarakteri (choʻl boʻrilari tezroq, yirik boʻrilar kuchliroq). Faqat shu ikki ustun qoʻlda kiritiladi.
A35: Vazn ustuni — haqiqiy zoologik oʻrtacha vazn; balansga taʼsir qilmaydi, faqat oʻyin ichidagi tavsif uchun.
A36: Barcha bazaviy raqamlar foydalanuvchi tasdigʻi bilan taklif qilingan boshlangʻich qiymatlar — test natijasiga qarab Sozlamalar varagʻidan oʻzgartiriladi.

Sheet Oziqlanish
A3: Oziqlanish — har daraja uchun kunlik ehtiyoj
A4: Toʻda hajmi Darajalar varagʻidan olinadi. Koʻk ustun — oʻlja vazni, qoʻlda sozlanadi.
A5: Daraja | B5: Boʻri nomi | C5: 1 boʻri (kg/kun) | D5: Toʻda hajmi | E5: Toʻda goʻshti (kg/kun) | F5: Suv (birlik/kun) | G5: Oy nuri (kun) | H5: Asosiy oʻlja | I5: Oʻlja vazni (kg) | J5: Ov soni (kun) | K5: 3 kunlik zaxira (kg) | L5: Kerakli Oziq gʻori darajasi
A6: 1 | B6: =Darajalar!B6 -> Honsyu boʻrisi | C6: =need_base+need_growth*(A6-1) -> 0.6 | D6: =Darajalar!O6 -> 1 | E6: =ROUND(C6*D6,0) -> 1 | F6: =ROUND((water_need_base+water_need_growth*(A6-1))*D6,0) -> 0 | G6: =IF(A6>=moonlight_need_level,moonlight_need*D6,0) -> 0 | H6: Kemiruvchi | I6: 0.5 | J6: =ROUNDUP(E6/I6,0) -> 2 | K6: =reserve_days*E6 -> 3 | L6: =MAX(1,ROUNDUP(LN(K6/store_base)/LN(store_growth),0)+1) -> 1
A7: 2 | B7: =Darajalar!B7 -> Efiopiya boʻrisi | C7: =need_base+need_growth*(A7-1) -> 0.7 | D7: =Darajalar!O7 -> 1 | E7: =ROUND(C7*D7,0) -> 1 | F7: =ROUND((water_need_base+water_need_growth*(A7-1))*D7,0) -> 0 | G7: =IF(A7>=moonlight_need_level,moonlight_need*D7,0) -> 0 | H7: Qush | I7: 1 | J7: =ROUNDUP(E7/I7,0) -> 1 | K7: =reserve_days*E7 -> 3 | L7: =MAX(1,ROUNDUP(LN(K7/store_base)/LN(store_growth),0)+1) -> 1
A8: 3 | B8: =Darajalar!B8 -> Arab boʻrisi | C8: =need_base+need_growth*(A8-1) -> 0.8 | D8: =Darajalar!O8 -> 1 | E8: =ROUND(C8*D8,0) -> 1 | F8: =ROUND((water_need_base+water_need_growth*(A8-1))*D8,0) -> 0 | G8: =IF(A8>=moonlight_need_level,moonlight_need*D8,0) -> 0 | H8: Quyon | I8: 2 | J8: =ROUNDUP(E8/I8,0) -> 1 | K8: =reserve_days*E8 -> 3 | L8: =MAX(1,ROUNDUP(LN(K8/store_base)/LN(store_growth),0)+1) -> 1
A9: 4 | B9: =Darajalar!B9 -> Hind boʻrisi | C9: =need_base+need_growth*(A9-1) -> 0.9 | D9: =Darajalar!O9 -> 10 | E9: =ROUND(C9*D9,0) -> 9 | F9: =ROUND((water_need_base+water_need_growth*(A9-1))*D9,0) -> 5 | G9: =IF(A9>=moonlight_need_level,moonlight_need*D9,0) -> 0 | H9: Sugʻur (toʻda ovi) | I9: 8 | J9: =ROUNDUP(E9/I9,0) -> 2 | K9: =reserve_days*E9 -> 27 | L9: =MAX(1,ROUNDUP(LN(K9/store_base)/LN(store_growth),0)+1) -> 1
A10: 5 | B10: =Darajalar!B10 -> Qizil boʻri | C10: =need_base+need_growth*(A10-1) -> 1 | D10: =Darajalar!O10 -> 12 | E10: =ROUND(C10*D10,0) -> 12 | F10: =ROUND((water_need_base+water_need_growth*(A10-1))*D10,0) -> 7 | G10: =IF(A10>=moonlight_need_level,moonlight_need*D10,0) -> 0 | H10: Jayron | I10: 25 | J10: =ROUNDUP(E10/I10,0) -> 1 | K10: =reserve_days*E10 -> 36 | L10: =MAX(1,ROUNDUP(LN(K10/store_base)/LN(store_growth),0)+1) -> 1
A11: 6 | B11: =Darajalar!B11 -> Italyan boʻrisi | C11: =need_base+need_growth*(A11-1) -> 1.1 | D11: =Darajalar!O11 -> 14 | E11: =ROUND(C11*D11,0) -> 15 | F11: =ROUND((water_need_base+water_need_growth*(A11-1))*D11,0) -> 8 | G11: =IF(A11>=moonlight_need_level,moonlight_need*D11,0) -> 0 | H11: Jayron | I11: 25 | J11: =ROUNDUP(E11/I11,0) -> 1 | K11: =reserve_days*E11 -> 45 | L11: =MAX(1,ROUNDUP(LN(K11/store_base)/LN(store_growth),0)+1) -> 2
A12: 7 | B12: =Darajalar!B12 -> Meksika boʻrisi | C12: =need_base+need_growth*(A12-1) -> 1.2 | D12: =Darajalar!O12 -> 17 | E12: =ROUND(C12*D12,0) -> 20 | F12: =ROUND((water_need_base+water_need_growth*(A12-1))*D12,0) -> 11 | G12: =IF(A12>=moonlight_need_level,moonlight_need*D12,0) -> 0 | H12: Yovvoyi choʻchqa | I12: 50 | J12: =ROUNDUP(E12/I12,0) -> 1 | K12: =reserve_days*E12 -> 60 | L12: =MAX(1,ROUNDUP(LN(K12/store_base)/LN(store_growth),0)+1) -> 4
A13: 8 | B13: =Darajalar!B13 -> Sharqiy boʻri | C13: =need_base+need_growth*(A13-1) -> 1.3 | D13: =Darajalar!O13 -> 21 | E13: =ROUND(C13*D13,0) -> 27 | F13: =ROUND((water_need_base+water_need_growth*(A13-1))*D13,0) -> 14 | G13: =IF(A13>=moonlight_need_level,moonlight_need*D13,0) -> 0 | H13: Yovvoyi choʻchqa | I13: 50 | J13: =ROUNDUP(E13/I13,0) -> 1 | K13: =reserve_days*E13 -> 81 | L13: =MAX(1,ROUNDUP(LN(K13/store_base)/LN(store_growth),0)+1) -> 5
A14: 9 | B14: =Darajalar!B14 -> Iberiya boʻrisi | C14: =need_base+need_growth*(A14-1) -> 1.4 | D14: =Darajalar!O14 -> 25 | E14: =ROUND(C14*D14,0) -> 35 | F14: =ROUND((water_need_base+water_need_growth*(A14-1))*D14,0) -> 18 | G14: =IF(A14>=moonlight_need_level,moonlight_need*D14,0) -> 0 | H14: Kiyik | I14: 60 | J14: =ROUNDUP(E14/I14,0) -> 1 | K14: =reserve_days*E14 -> 105 | L14: =MAX(1,ROUNDUP(LN(K14/store_base)/LN(store_growth),0)+1) -> 6
A15: 10 | B15: =Darajalar!B15 -> Dasht boʻrisi | C15: =need_base+need_growth*(A15-1) -> 1.5 | D15: =Darajalar!O15 -> 30 | E15: =ROUND(C15*D15,0) -> 45 | F15: =ROUND((water_need_base+water_need_growth*(A15-1))*D15,0) -> 23 | G15: =IF(A15>=moonlight_need_level,moonlight_need*D15,0) -> 0 | H15: Kiyik | I15: 60 | J15: =ROUNDUP(E15/I15,0) -> 1 | K15: =reserve_days*E15 -> 135 | L15: =MAX(1,ROUNDUP(LN(K15/store_base)/LN(store_growth),0)+1) -> 8
A16: 11 | B16: =Darajalar!B16 -> Himolay boʻrisi | C16: =need_base+need_growth*(A16-1) -> 1.6 | D16: =Darajalar!O16 -> 36 | E16: =ROUND(C16*D16,0) -> 58 | F16: =ROUND((water_need_base+water_need_growth*(A16-1))*D16,0) -> 29 | G16: =IF(A16>=moonlight_need_level,moonlight_need*D16,0) -> 0 | H16: Bugʻu | I16: 100 | J16: =ROUNDUP(E16/I16,0) -> 1 | K16: =reserve_days*E16 -> 174 | L16: =MAX(1,ROUNDUP(LN(K16/store_base)/LN(store_growth),0)+1) -> 9
A17: 12 | B17: =Darajalar!B17 -> Ezo boʻrisi | C17: =need_base+need_growth*(A17-1) -> 1.7 | D17: =Darajalar!O17 -> 43 | E17: =ROUND(C17*D17,0) -> 73 | F17: =ROUND((water_need_base+water_need_growth*(A17-1))*D17,0) -> 36 | G17: =IF(A17>=moonlight_need_level,moonlight_need*D17,0) -> 0 | H17: Bugʻu | I17: 100 | J17: =ROUNDUP(E17/I17,0) -> 1 | K17: =reserve_days*E17 -> 219 | L17: =MAX(1,ROUNDUP(LN(K17/store_base)/LN(store_growth),0)+1) -> 10
... A30: 25 | B30: =Darajalar!B30 -> Koʻk Boʻri | C30: =need_base+need_growth*(A30-1) -> 3 | D30: =Darajalar!O30 -> 460 | E30: =ROUND(C30*D30,0) -> 1380 | F30: =ROUND((water_need_base+water_need_growth*(A30-1))*D30,0) -> 626 | G30: =IF(A30>=moonlight_need_level,moonlight_need*D30,0) -> 92 | H30: Ruh oʻljasi | I30: 400 | J30: =ROUNDUP(E30/I30,0) -> 4 | K30: =reserve_days*E30 -> 4140 | L30: =MAX(1,ROUNDUP(LN(K30/store_base)/LN(store_growth),0)+1) -> 25
A31: Formulalar: 1 boʻri ehtiyoji = Bazaviy + Oʻsish×(daraja-1) · Toʻda goʻshti = shu × toʻda hajmi · Ov soni = toʻda goʻshti ÷ oʻlja vazni (yuqoriga yaxlitlanadi)
A32: Kerakli gʻor darajasi = 3 kunlik zaxirani sigʻdiradigan eng kichik daraja. Bu oʻyinchini boʻri darajasi bilan birga omborni ham kuchaytirishga majbur qiladi.
A33: Oy nuri faqat 20-darajadan boshlab talab qilinadi — mifologik bosqichning sunʼiy cheklovi.

Sheet Binolar
A3: Binolar — kuchaytirish narxi va samarasi (1–25 daraja)
A4: Har bino oʻyinchi darajasigacha koʻtariladi: bino darajasi = maksimum oʻyinchi darajasi.
A5: 1. OZIQ GʻORI — goʻsht, suv, shifobaxsh oʻt va oy nuri saqlaydi (har biri alohida sigʻim)
A6: Daraja | B6: Sigʻim | C6: Passiv suv (soat) | D6: Oflayn sigʻim (2×) | E6: Himoya | F6: Narx: tosh | G6: Narx: shox-shabba | H6: Qurilish vaqti (soat)
A7: 1 | B7: =ROUND(store_base*store_growth^(A7-1),0) -> 40 | C7: =ROUND(water_passive_base*water_passive_growth^(A7-1),1) -> 0.3 | D7: =B7*offline_store_mult -> 80 | E7: =cave_protect_base+cave_protect_growth*(A7-1) -> 0.3 | F7: =IF(A7=1,0,ROUND(cost_food_cave_stone*1*cost_growth^(A7-2)*IF(A7<=4,stage_early,IF(A7<=stage_mid_level,stage_mid,IF(A7<=stage_late_level,stage_normal,stage_late))),0)) -> 0 | G7: =IF(A7=1,0,ROUND(cost_food_cave_wood*1*cost_growth^(A7-2)*IF(A7<=4,stage_early,IF(A7<=stage_mid_level,stage_mid,IF(A7<=stage_late_level,stage_normal,stage_late))),0)) -> 0 | H7: =IF(A7=1,0,ROUND(build_time_base_min*time_coef_food_cave*time_growth^(A7-2)*IF(A7<=4,stage_early,IF(A7<=stage_mid_level,stage_mid,IF(A7<=stage_late_level,stage_normal,stage_late)))/60,1)) -> 0
A8: 2 | B8: =ROUND(store_base*store_growth^(A8-1),0) -> 49 | C8: =ROUND(water_passive_base*water_passive_growth^(A8-1),1) -> 0.3 | D8: =B8*offline_store_mult -> 98 | E8: =cave_protect_base+cave_protect_growth*(A8-1) -> 0.32 | F8: =IF(A8=1,0,ROUND(cost_food_cave_stone*1*cost_growth^(A8-2)*IF(A8<=4,stage_early,IF(A8<=stage_mid_level,stage_mid,IF(A8<=stage_late_level,stage_normal,stage_late))),0)) -> 40 | G8: =IF(A8=1,0,ROUND(cost_food_cave_wood*1*cost_growth^(A8-2)*IF(A8<=4,stage_early,IF(A8<=stage_mid_level,stage_mid,IF(A8<=stage_late_level,stage_normal,stage_late))),0)) -> 24 | H8: =IF(A8=1,0,ROUND(build_time_base_min*time_coef_food_cave*time_growth^(A8-2)*IF(A8<=4,stage_early,IF(A8<=stage_mid_level,stage_mid,IF(A8<=stage_late_level,stage_normal,stage_late)))/60,1)) -> 0.1
A9: 3 | B9: =ROUND(store_base*store_growth^(A9-1),0) -> 60 | C9: =ROUND(water_passive_base*water_passive_growth^(A9-1),1) -> 0.4 | D9: =B9*offline_store_mult -> 120 | E9: =cave_protect_base+cave_protect_growth*(A9-1) -> 0.34 | F9: =IF(A9=1,0,ROUND(cost_food_cave_stone*1*cost_growth^(A9-2)*IF(A9<=4,stage_early,IF(A9<=stage_mid_level,stage_mid,IF(A9<=stage_late_level,stage_normal,stage_late))),0)) -> 52 | G9: =IF(A9=1,0,ROUND(cost_food_cave_wood*1*cost_growth^(A9-2)*IF(A9<=4,stage_early,IF(A9<=stage_mid_level,stage_mid,IF(A9<=stage_late_level,stage_normal,stage_late))),0)) -> 31 | H9: =IF(A9=1,0,ROUND(build_time_base_min*time_coef_food_cave*time_growth^(A9-2)*IF(A9<=4,stage_early,IF(A9<=stage_mid_level,stage_mid,IF(A9<=stage_late_level,stage_normal,stage_late)))/60,1)) -> 0.1
A10: 4 | B10: =ROUND(store_base*store_growth^(A10-1),0) -> 73 | C10: =ROUND(water_passive_base*water_passive_growth^(A10-1),1) -> 0.5 | D10: =B10*offline_store_mult -> 146 | E10: =cave_protect_base+cave_protect_growth*(A10-1) -> 0.36 | F10: =IF(A10=1,0,ROUND(cost_food_cave_stone*1*cost_growth^(A10-2)*IF(A10<=4,stage_early,IF(A10<=stage_mid_level,stage_mid,IF(A10<=stage_late_level,stage_normal,stage_late))),0)) -> 68 | G10: =IF(A10=1,0,ROUND(cost_food_cave_wood*1*cost_growth^(A10-2)*IF(A10<=4,stage_early,IF(A10<=stage_mid_level,stage_mid,IF(A10<=stage_late_level,stage_normal,stage_late))),0)) -> 41 | H10: =IF(A10=1,0,ROUND(build_time_base_min*time_coef_food_cave*time_growth^(A10-2)*IF(A10<=4,stage_early,IF(A10<=stage_mid_level,stage_mid,IF(A10<=stage_late_level,stage_normal,stage_late)))/60,1)) -> 0.1
A11: 5 | B11: =ROUND(store_base*store_growth^(A11-1),0) -> 89 | C11: =ROUND(water_passive_base*water_passive_growth^(A11-1),1) -> 0.6 | D11: =B11*offline_store_mult -> 178 | E11: =cave_protect_base+cave_protect_growth*(A11-1) -> 0.38 | F11: =IF(A11=1,0,ROUND(cost_food_cave_stone*1*cost_growth^(A11-2)*IF(A11<=4,stage_early,IF(A11<=stage_mid_level,stage_mid,IF(A11<=stage_late_level,stage_normal,stage_late))),0)) -> 154 | G11: =IF(A11=1,0,ROUND(cost_food_cave_wood*1*cost_growth^(A11-2)*IF(A11<=4,stage_early,IF(A11<=stage_mid_level,stage_mid,IF(A11<=stage_late_level,stage_normal,stage_late))),0)) -> 92 | H11: =IF(A11=1,0,ROUND(build_time_base_min*time_coef_food_cave*time_growth^(A11-2)*IF(A11<=4,stage_early,IF(A11<=stage_mid_level,stage_mid,IF(A11<=stage_late_level,stage_normal,stage_late)))/60,1)) -> 0.2
A12: 6 | B12: =ROUND(store_base*store_growth^(A12-1),0) -> 108 | C12: =ROUND(water_passive_base*water_passive_growth^(A12-1),1) -> 0.8 | D12: =B12*offline_store_mult -> 216 | E12: =cave_protect_base+cave_protect_growth*(A12-1) -> 0.4 | F12: =IF(A12=1,0,ROUND(cost_food_cave_stone*1*cost_growth^(A12-2)*IF(A12<=4,stage_early,IF(A12<=stage_mid_level,stage_mid,IF(A12<=stage_late_level,stage_normal,stage_late))),0)) -> 200 | G12: =IF(A12=1,0,ROUND(cost_food_cave_wood*1*cost_growth^(A12-2)*IF(A12<=4,stage_early,IF(A12<=stage_mid_level,stage_mid,IF(A12<=stage_late_level,stage_normal,stage_late))),0)) -> 120 | H12: =IF(A12=1,0,ROUND(build_time_base_min*time_coef_food_cave*time_growth^(A12-2)*IF(A12<=4,stage_early,IF(A12<=stage_mid_level,stage_mid,IF(A12<=stage_late_level,stage_normal,stage_late)))/60,1)) -> 0.3
A13: 7 | B13: =ROUND(store_base*store_growth^(A13-1),0) -> 132 | C13: =ROUND(water_passive_base*water_passive_growth^(A13-1),1) -> 1 | D13: =B13*offline_store_mult -> 264 | E13: =cave_protect_base+cave_protect_growth*(A13-1) -> 0.42 | F13: =IF(A13=1,0,ROUND(cost_food_cave_stone*1*cost_growth^(A13-2)*IF(A13<=4,stage_early,IF(A13<=stage_mid_level,stage_mid,IF(A13<=stage_late_level,stage_normal,stage_late))),0)) -> 260 | G13: =IF(A13=1,0,ROUND(cost_food_cave_wood*1*cost_growth^(A13-2)*IF(A13<=4,stage_early,IF(A13<=stage_mid_level,stage_mid,IF(A13<=stage_late_level,stage_normal,stage_late))),0)) -> 156 | H13: =IF(A13=1,0,ROUND(build_time_base_min*time_coef_food_cave*time_growth^(A13-2)*IF(A13<=4,stage_early,IF(A13<=stage_mid_level,stage_mid,IF(A13<=stage_late_level,stage_normal,stage_late)))/60,1)) -> 0.4
A14: 8 | B14: =ROUND(store_base*store_growth^(A14-1),0) -> 161 | C14: =ROUND(water_passive_base*water_passive_growth^(A14-1),1) -> 1.2 | D14: =B14*offline_store_mult -> 322 | E14: =cave_protect_base+cave_protect_growth*(A14-1) -> 0.44 | F14: =IF(A14=1,0,ROUND(cost_food_cave_stone*1*cost_growth^(A14-2)*IF(A14<=4,stage_early,IF(A14<=stage_mid_level,stage_mid,IF(A14<=stage_late_level,stage_normal,stage_late))),0)) -> 338 | G14: =IF(A14=1,0,ROUND(cost_food_cave_wood*1*cost_growth^(A14-2)*IF(A14<=4,stage_early,IF(A14<=stage_mid_level,stage_mid,IF(A14<=stage_late_level,stage_normal,stage_late))),0)) -> 203 | H14: =IF(A14=1,0,ROUND(build_time_base_min*time_coef_food_cave*time_growth^(A14-2)*IF(A14<=4,stage_early,IF(A14<=stage_mid_level,stage_mid,IF(A14<=stage_late_level,stage_normal,stage_late)))/60,1)) -> 0.4
A15: 9 | B15: =ROUND(store_base*store_growth^(A15-1),0) -> 196 | C15: =ROUND(water_passive_base*water_passive_growth^(A15-1),1) -> 1.5 | D15: =B15*offline_store_mult -> 392 | E15: =cave_protect_base+cave_protect_growth*(A15-1) -> 0.46 | F15: =IF(A15=1,0,ROUND(cost_food_cave_stone*1*cost_growth^(A15-2)*IF(A15<=4,stage_early,IF(A15<=stage_mid_level,stage_mid,IF(A15<=stage_late_level,stage_normal,stage_late))),0)) -> 439 | G15: =IF(A15=1,0,ROUND(cost_food_cave_wood*1*cost_growth^(A15-2)*IF(A15<=4,stage_early,IF(A15<=stage_mid_level,stage_mid,IF(A15<=stage_late_level,stage_normal,stage_late))),0)) -> 264 | H15: =IF(A15=1,0,ROUND(build_time_base_min*time_coef_food_cave*time_growth^(A15-2)*IF(A15<=4,stage_early,IF(A15<=stage_mid_level,stage_mid,IF(A15<=stage_late_level,stage_normal,stage_late)))/60,1)) -> 0.6
A16: 10 | B16: =ROUND(store_base*store_growth^(A16-1),0) -> 239 | C16: =ROUND(water_passive_base*water_passive_growth^(A16-1),1) -> 1.9 | D16: =B16*offline_store_mult -> 478 | E16: =cave_protect_base+cave_protect_growth*(A16-1) -> 0.48 | F16: =IF(A16=1,0,ROUND(cost_food_cave_stone*1*cost_growth^(A16-2)*IF(A16<=4,stage_early,IF(A16<=stage_mid_level,stage_mid,IF(A16<=stage_late_level,stage_normal,stage_late))),0)) -> 571 | G16: =IF(A16=1,0,ROUND(cost_food_cave_wood*1*cost_growth^(A16-2)*IF(A16<=4,stage_early,IF(A16<=stage_mid_level,stage_mid,IF(A16<=stage_late_level,stage_normal,stage_late))),0)) -> 343 | H16: =IF(A16=1,0,ROUND(build_time_base_min*time_coef_food_cave*time_growth^(A16-2)*IF(A16<=4,stage_early,IF(A16<=stage_mid_level,stage_mid,IF(A16<=stage_late_level,stage_normal,stage_late)))/60,1)) -> 0.7
A17: 11 | B17: =ROUND(store_base*store_growth^(A17-1),0) -> 292 | C17: =ROUND(water_passive_base*water_passive_growth^(A17-1),1) -> 2.3 | D17: =B17*offline_store_mult -> 584 | E17: =cave_protect_base+cave_protect_growth*(A17-1) -> 0.5 | F17: =IF(A17=1,0,ROUND(cost_food_cave_stone*1*cost_growth^(A17-2)*IF(A17<=4,stage_early,IF(A17<=stage_mid_level,stage_mid,IF(A17<=stage_late_level,stage_normal,stage_late))),0)) -> 1060 | G17: =IF(A17=1,0,ROUND(cost_food_cave_wood*1*cost_growth^(A17-2)*IF(A17<=4,stage_early,IF(A17<=stage_mid_level,stage_mid,IF(A17<=stage_late_level,stage_normal,stage_late))),0)) -> 636 | H17: =IF(A17=1,0,ROUND(build_time_base_min*time_coef_food_cave*time_growth^(A17-2)*IF(A17<=4,stage_early,IF(A17<=stage_mid_level,stage_mid,IF(A17<=stage_late_level,stage_normal,stage_late)))/60,1)) -> 1.2
A18: 12 | B18: =ROUND(store_base*store_growth^(A18-1),0) -> 356 | C18: =ROUND(water_passive_base*water_passive_growth^(A18-1),1) -> 2.9 | D18: =B18*offline_store_mult -> 712 | E18: =cave_protect_base+cave_protect_growth*(A18-1) -> 0.52 | F18: =IF(A18=1,0,ROUND(cost_food_cave_stone*1*cost_growth^(A18-2)*IF(A18<=4,stage_early,IF(A18<=stage_mid_level,stage_mid,IF(A18<=stage_late_level,stage_normal,stage_late))),0)) -> 1379 | G18: =IF(A18=1,0,ROUND(cost_food_cave_wood*1*cost_growth^(A18-2)*IF(A18<=4,stage_early,IF(A18<=stage_mid_level,stage_mid,IF(A18<=stage_late_level,stage_normal,stage_late))),0)) -> 827 | H18: =IF(A18=1,0,ROUND(build_time_base_min*time_coef_food_cave*time_growth^(A18-2)*IF(A18<=4,stage_early,IF(A18<=stage_mid_level,stage_mid,IF(A18<=stage_late_level,stage_normal,stage_late)))/60,1)) -> 1.6
... A31: 25 | B31: =ROUND(store_base*store_growth^(A31-1),0) -> 4728 | C31: =ROUND(water_passive_base*water_passive_growth^(A31-1),1) -> 52.9 | D31: =B31*offline_store_mult -> 9456 | E31: =cave_protect_base+cave_protect_growth*(A31-1) -> 0.78 | F31: =IF(A31=1,0,ROUND(cost_food_cave_stone*1*cost_growth^(A31-2)*IF(A31<=4,stage_early,IF(A31<=stage_mid_level,stage_mid,IF(A31<=stage_late_level,stage_normal,stage_late))),0)) -> 52192 | G31: =IF(A31=1,0,ROUND(cost_food_cave_wood*1*cost_growth^(A31-2)*IF(A31<=4,stage_early,IF(A31<=stage_mid_level,stage_mid,IF(A31<=stage_late_level,stage_normal,stage_late))),0)) -> 31315 | H31: =IF(A31=1,0,ROUND(build_time_base_min*time_coef_food_cave*time_growth^(A31-2)*IF(A31<=4,stage_early,IF(A31<=stage_mid_level,stage_mid,IF(A31<=stage_late_level,stage_normal,stage_late)))/60,1)) -> 35.3
A32: 2. USTAXONA QOYASI — tosh, shox-shabba, teri, suyak yigʻadi
A33: Daraja | B33: Ishlab chiqarish (soat) | C33: Kunlik ishlab chiqarish | D33: Bufer (10 soat) | E33: Oflayn bufer (2×) | F33: Narx: tosh | G33: Narx: shox-shabba | H33: Narx: suyak | I33: Qurilish vaqti (soat)
A34: 1 | B34: =ROUND(prod_base*prod_growth^(A34-1),0) -> 20 | C34: =ROUND(prod_base*prod_growth^(A34-1)*24,0) -> 480 | D34: =B34*workshop_buffer_h -> 200 | E34: =D34*offline_store_mult -> 400 | F34: =IF(A34=1,0,ROUND(cost_workshop_stone*1*cost_growth^(A34-2)*IF(A34<=4,stage_early,IF(A34<=stage_mid_level,stage_mid,IF(A34<=stage_late_level,stage_normal,stage_late))),0)) -> 0 | G34: =IF(A34=1,0,ROUND(cost_workshop_wood*1*cost_growth^(A34-2)*IF(A34<=4,stage_early,IF(A34<=stage_mid_level,stage_mid,IF(A34<=stage_late_level,stage_normal,stage_late))),0)) -> 0 | H34: =IF(A34=1,0,ROUND(cost_workshop_bone*1*cost_growth^(A34-2)*IF(A34<=4,stage_early,IF(A34<=stage_mid_level,stage_mid,IF(A34<=stage_late_level,stage_normal,stage_late))),0)) -> 0 | I34: =IF(A34=1,0,ROUND(build_time_base_min*time_coef_workshop*time_growth^(A34-2)*IF(A34<=4,stage_early,IF(A34<=stage_mid_level,stage_mid,IF(A34<=stage_late_level,stage_normal,stage_late)))/60,1)) -> 0
A35: 2 | B35: =ROUND(prod_base*prod_growth^(A35-1),0) -> 24 | C35: =ROUND(prod_base*prod_growth^(A35-1)*24,0) -> 586 | D35: =B35*workshop_buffer_h -> 240 | E35: =D35*offline_store_mult -> 480 | F35: =IF(A35=1,0,ROUND(cost_workshop_stone*1*cost_growth^(A35-2)*IF(A35<=4,stage_early,IF(A35<=stage_mid_level,stage_mid,IF(A35<=stage_late_level,stage_normal,stage_late))),0)) -> 60 | G35: =IF(A35=1,0,ROUND(cost_workshop_wood*1*cost_growth^(A35-2)*IF(A35<=4,stage_early,IF(A35<=stage_mid_level,stage_mid,IF(A35<=stage_late_level,stage_normal,stage_late))),0)) -> 40 | H35: =IF(A35=1,0,ROUND(cost_workshop_bone*1*cost_growth^(A35-2)*IF(A35<=4,stage_early,IF(A35<=stage_mid_level,stage_mid,IF(A35<=stage_late_level,stage_normal,stage_late))),0)) -> 16 | I35: =IF(A35=1,0,ROUND(build_time_base_min*time_coef_workshop*time_growth^(A35-2)*IF(A35<=4,stage_early,IF(A35<=stage_mid_level,stage_mid,IF(A35<=stage_late_level,stage_normal,stage_late)))/60,1)) -> 0.1
A36: 3 | B36: =ROUND(prod_base*prod_growth^(A36-1),0) -> 30 | C36: =ROUND(prod_base*prod_growth^(A36-1)*24,0) -> 714 | D36: =B36*workshop_buffer_h -> 300 | E36: =D36*offline_store_mult -> 600 | F36: =IF(A36=1,0,ROUND(cost_workshop_stone*1*cost_growth^(A36-2)*IF(A36<=4,stage_early,IF(A36<=stage_mid_level,stage_mid,IF(A36<=stage_late_level,stage_normal,stage_late))),0)) -> 78 | G36: =IF(A36=1,0,ROUND(cost_workshop_wood*1*cost_growth^(A36-2)*IF(A36<=4,stage_early,IF(A36<=stage_mid_level,stage_mid,IF(A36<=stage_late_level,stage_normal,stage_late))),0)) -> 52 | H36: =IF(A36=1,0,ROUND(cost_workshop_bone*1*cost_growth^(A36-2)*IF(A36<=4,stage_early,IF(A36<=stage_mid_level,stage_mid,IF(A36<=stage_late_level,stage_normal,stage_late))),0)) -> 21 | I36: =IF(A36=1,0,ROUND(build_time_base_min*time_coef_workshop*time_growth^(A36-2)*IF(A36<=4,stage_early,IF(A36<=stage_mid_level,stage_mid,IF(A36<=stage_late_level,stage_normal,stage_late)))/60,1)) -> 0.1
A37: 4 | B37: =ROUND(prod_base*prod_growth^(A37-1),0) -> 36 | C37: =ROUND(prod_base*prod_growth^(A37-1)*24,0) -> 872 | D37: =B37*workshop_buffer_h -> 360 | E37: =D37*offline_store_mult -> 720 | F37: =IF(A37=1,0,ROUND(cost_workshop_stone*1*cost_growth^(A37-2)*IF(A37<=4,stage_early,IF(A37<=stage_mid_level,stage_mid,IF(A37<=stage_late_level,stage_normal,stage_late))),0)) -> 101 | G37: =IF(A37=1,0,ROUND(cost_workshop_wood*1*cost_growth^(A37-2)*IF(A37<=4,stage_early,IF(A37<=stage_mid_level,stage_mid,IF(A37<=stage_late_level,stage_normal,stage_late))),0)) -> 68 | H37: =IF(A37=1,0,ROUND(cost_workshop_bone*1*cost_growth^(A37-2)*IF(A37<=4,stage_early,IF(A37<=stage_mid_level,stage_mid,IF(A37<=stage_late_level,stage_normal,stage_late))),0)) -> 27 | I37: =IF(A37=1,0,ROUND(build_time_base_min*time_coef_workshop*time_growth^(A37-2)*IF(A37<=4,stage_early,IF(A37<=stage_mid_level,stage_mid,IF(A37<=stage_late_level,stage_normal,stage_late)))/60,1)) -> 0.1
A38: 5 | B38: =ROUND(prod_base*prod_growth^(A38-1),0) -> 44 | C38: =ROUND(prod_base*prod_growth^(A38-1)*24,0) -> 1063 | D38: =B38*workshop_buffer_h -> 440 | E38: =D38*offline_store_mult -> 880 | F38: =IF(A38=1,0,ROUND(cost_workshop_stone*1*cost_growth^(A38-2)*IF(A38<=4,stage_early,IF(A38<=stage_mid_level,stage_mid,IF(A38<=stage_late_level,stage_normal,stage_late))),0)) -> 231 | G38: =IF(A38=1,0,ROUND(cost_workshop_wood*1*cost_growth^(A38-2)*IF(A38<=4,stage_early,IF(A38<=stage_mid_level,stage_mid,IF(A38<=stage_late_level,stage_normal,stage_late))),0)) -> 154 | H38: =IF(A38=1,0,ROUND(cost_workshop_bone*1*cost_growth^(A38-2)*IF(A38<=4,stage_early,IF(A38<=stage_mid_level,stage_mid,IF(A38<=stage_late_level,stage_normal,stage_late))),0)) -> 62 | I38: =IF(A38=1,0,ROUND(build_time_base_min*time_coef_workshop*time_growth^(A38-2)*IF(A38<=4,stage_early,IF(A38<=stage_mid_level,stage_mid,IF(A38<=stage_late_level,stage_normal,stage_late)))/60,1)) -> 0.3
A39: 6 | B39: =ROUND(prod_base*prod_growth^(A39-1),0) -> 54 | C39: =ROUND(prod_base*prod_growth^(A39-1)*24,0) -> 1297 | D39: =B39*workshop_buffer_h -> 540 | E39: =D39*offline_store_mult -> 1080 | F39: =IF(A39=1,0,ROUND(cost_workshop_stone*1*cost_growth^(A39-2)*IF(A39<=4,stage_early,IF(A39<=stage_mid_level,stage_mid,IF(A39<=stage_late_level,stage_normal,stage_late))),0)) -> 300 | G39: =IF(A39=1,0,ROUND(cost_workshop_wood*1*cost_growth^(A39-2)*IF(A39<=4,stage_early,IF(A39<=stage_mid_level,stage_mid,IF(A39<=stage_late_level,stage_normal,stage_late))),0)) -> 200 | H39: =IF(A39=1,0,ROUND(cost_workshop_bone*1*cost_growth^(A39-2)*IF(A39<=4,stage_early,IF(A39<=stage_mid_level,stage_mid,IF(A39<=stage_late_level,stage_normal,stage_late))),0)) -> 80 | I39: =IF(A39=1,0,ROUND(build_time_base_min*time_coef_workshop*time_growth^(A39-2)*IF(A39<=4,stage_early,IF(A39<=stage_mid_level,stage_mid,IF(A39<=stage_late_level,stage_normal,stage_late)))/60,1)) -> 0.3
A40: 7 | B40: =ROUND(prod_base*prod_growth^(A40-1),0) -> 66 | C40: =ROUND(prod_base*prod_growth^(A40-1)*24,0) -> 1583 | D40: =B40*workshop_buffer_h -> 660 | E40: =D40*offline_store_mult -> 1320 | F40: =IF(A40=1,0,ROUND(cost_workshop_stone*1*cost_growth^(A40-2)*IF(A40<=4,stage_early,IF(A40<=stage_mid_level,stage_mid,IF(A40<=stage_late_level,stage_normal,stage_late))),0)) -> 390 | G40: =IF(A40=1,0,ROUND(cost_workshop_wood*1*cost_growth^(A40-2)*IF(A40<=4,stage_early,IF(A40<=stage_mid_level,stage_mid,IF(A40<=stage_late_level,stage_normal,stage_late))),0)) -> 260 | H40: =IF(A40=1,0,ROUND(cost_workshop_bone*1*cost_growth^(A40-2)*IF(A40<=4,stage_early,IF(A40<=stage_mid_level,stage_mid,IF(A40<=stage_late_level,stage_normal,stage_late))),0)) -> 104 | I40: =IF(A40=1,0,ROUND(build_time_base_min*time_coef_workshop*time_growth^(A40-2)*IF(A40<=4,stage_early,IF(A40<=stage_mid_level,stage_mid,IF(A40<=stage_late_level,stage_normal,stage_late)))/60,1)) -> 0.4
A41: 8 | B41: =ROUND(prod_base*prod_growth^(A41-1),0) -> 80 | C41: =ROUND(prod_base*prod_growth^(A41-1)*24,0) -> 1931 | D41: =B41*workshop_buffer_h -> 800 | E41: =D41*offline_store_mult -> 1600 | F41: =IF(A41=1,0,ROUND(cost_workshop_stone*1*cost_growth^(A41-2)*IF(A41<=4,stage_early,IF(A41<=stage_mid_level,stage_mid,IF(A41<=stage_late_level,stage_normal,stage_late))),0)) -> 507 | G41: =IF(A41=1,0,ROUND(cost_workshop_wood*1*cost_growth^(A41-2)*IF(A41<=4,stage_early,IF(A41<=stage_mid_level,stage_mid,IF(A41<=stage_late_level,stage_normal,stage_late))),0)) -> 338 | H41: =IF(A41=1,0,ROUND(cost_workshop_bone*1*cost_growth^(A41-2)*IF(A41<=4,stage_early,IF(A41<=stage_mid_level,stage_mid,IF(A41<=stage_late_level,stage_normal,stage_late))),0)) -> 135 | I41: =IF(A41=1,0,ROUND(build_time_base_min*time_coef_workshop*time_growth^(A41-2)*IF(A41<=4,stage_early,IF(A41<=stage_mid_level,stage_mid,IF(A41<=stage_late_level,stage_normal,stage_late)))/60,1)) -> 0.5
A42: 9 | B42: =ROUND(prod_base*prod_growth^(A42-1),0) -> 98 | C42: =ROUND(prod_base*prod_growth^(A42-1)*24,0) -> 2356 | D42: =B42*workshop_buffer_h -> 980 | E42: =D42*offline_store_mult -> 1960 | F42: =IF(A42=1,0,ROUND(cost_workshop_stone*1*cost_growth^(A42-2)*IF(A42<=4,stage_early,IF(A42<=stage_mid_level,stage_mid,IF(A42<=stage_late_level,stage_normal,stage_late))),0)) -> 659 | G42: =IF(A42=1,0,ROUND(cost_workshop_wood*1*cost_growth^(A42-2)*IF(A42<=4,stage_early,IF(A42<=stage_mid_level,stage_mid,IF(A42<=stage_late_level,stage_normal,stage_late))),0)) -> 439 | H42: =IF(A42=1,0,ROUND(cost_workshop_bone*1*cost_growth^(A42-2)*IF(A42<=4,stage_early,IF(A42<=stage_mid_level,stage_mid,IF(A42<=stage_late_level,stage_normal,stage_late))),0)) -> 176 | I42: =IF(A42=1,0,ROUND(build_time_base_min*time_coef_workshop*time_growth^(A42-2)*IF(A42<=4,stage_early,IF(A42<=stage_mid_level,stage_mid,IF(A42<=stage_late_level,stage_normal,stage_late)))/60,1)) -> 0.7
A43: 10 | B43: =ROUND(prod_base*prod_growth^(A43-1),0) -> 120 | C43: =ROUND(prod_base*prod_growth^(A43-1)*24,0) -> 2874 | D43: =B43*workshop_buffer_h -> 1200 | E43: =D43*offline_store_mult -> 2400 | F43: =IF(A43=1,0,ROUND(cost_workshop_stone*1*cost_growth^(A43-2)*IF(A43<=4,stage_early,IF(A43<=stage_mid_level,stage_mid,IF(A43<=stage_late_level,stage_normal,stage_late))),0)) -> 857 | G43: =IF(A43=1,0,ROUND(cost_workshop_wood*1*cost_growth^(A43-2)*IF(A43<=4,stage_early,IF(A43<=stage_mid_level,stage_mid,IF(A43<=stage_late_level,stage_normal,stage_late))),0)) -> 571 | H43: =IF(A43=1,0,ROUND(cost_workshop_bone*1*cost_growth^(A43-2)*IF(A43<=4,stage_early,IF(A43<=stage_mid_level,stage_mid,IF(A43<=stage_late_level,stage_normal,stage_late))),0)) -> 228 | I43: =IF(A43=1,0,ROUND(build_time_base_min*time_coef_workshop*time_growth^(A43-2)*IF(A43<=4,stage_early,IF(A43<=stage_mid_level,stage_mid,IF(A43<=stage_late_level,stage_normal,stage_late)))/60,1)) -> 0.8
A44: 11 | B44: =ROUND(prod_base*prod_growth^(A44-1),0) -> 146 | C44: =ROUND(prod_base*prod_growth^(A44-1)*24,0) -> 3506 | D44: =B44*workshop_buffer_h -> 1460 | E44: =D44*offline_store_mult -> 2920 | F44: =IF(A44=1,0,ROUND(cost_workshop_stone*1*cost_growth^(A44-2)*IF(A44<=4,stage_early,IF(A44<=stage_mid_level,stage_mid,IF(A44<=stage_late_level,stage_normal,stage_late))),0)) -> 1591 | G44: =IF(A44=1,0,ROUND(cost_workshop_wood*1*cost_growth^(A44-2)*IF(A44<=4,stage_early,IF(A44<=stage_mid_level,stage_mid,IF(A44<=stage_late_level,stage_normal,stage_late))),0)) -> 1060 | H44: =IF(A44=1,0,ROUND(cost_workshop_bone*1*cost_growth^(A44-2)*IF(A44<=4,stage_early,IF(A44<=stage_mid_level,stage_mid,IF(A44<=stage_late_level,stage_normal,stage_late))),0)) -> 424 | I44: =IF(A44=1,0,ROUND(build_time_base_min*time_coef_workshop*time_growth^(A44-2)*IF(A44<=4,stage_early,IF(A44<=stage_mid_level,stage_mid,IF(A44<=stage_late_level,stage_normal,stage_late)))/60,1)) -> 1.5
A45: 12 | B45: =ROUND(prod_base*prod_growth^(A45-1),0) -> 178 | C45: =ROUND(prod_base*prod_growth^(A45-1)*24,0) -> 4278 | D45: =B45*workshop_buffer_h -> 1780 | E45: =D45*offline_store_mult -> 3560 | F45: =IF(A45=1,0,ROUND(cost_workshop_stone*1*cost_growth^(A45-2)*IF(A45<=4,stage_early,IF(A45<=stage_mid_level,stage_mid,IF(A45<=stage_late_level,stage_normal,stage_late))),0)) -> 2068 | G45: =IF(A45=1,0,ROUND(cost_workshop_wood*1*cost_growth^(A45-2)*IF(A45<=4,stage_early,IF(A45<=stage_mid_level,stage_mid,IF(A45<=stage_late_level,stage_normal,stage_late))),0)) -> 1379 | H45: =IF(A45=1,0,ROUND(cost_workshop_bone*1*cost_growth^(A45-2)*IF(A45<=4,stage_early,IF(A45<=stage_mid_level,stage_mid,IF(A45<=stage_late_level,stage_normal,stage_late))),0)) -> 551 | I45: =IF(A45=1,0,ROUND(build_time_base_min*time_coef_workshop*time_growth^(A45-2)*IF(A45<=4,stage_early,IF(A45<=stage_mid_level,stage_mid,IF(A45<=stage_late_level,stage_normal,stage_late)))/60,1)) -> 1.9
... A58: 25 | B58: =ROUND(prod_base*prod_growth^(A58-1),0) -> 2364 | C58: =ROUND(prod_base*prod_growth^(A58-1)*24,0) -> 56738 | D58: =B58*workshop_buffer_h -> 23640 | E58: =D58*offline_store_mult -> 47280 | F58: =IF(A58=1,0,ROUND(cost_workshop_stone*1*cost_growth^(A58-2)*IF(A58<=4,stage_early,IF(A58<=stage_mid_level,stage_mid,IF(A58<=stage_late_level,stage_normal,stage_late))),0)) -> 78289 | G58: =IF(A58=1,0,ROUND(cost_workshop_wood*1*cost_growth^(A58-2)*IF(A58<=4,stage_early,IF(A58<=stage_mid_level,stage_mid,IF(A58<=stage_late_level,stage_normal,stage_late))),0)) -> 52192 | H58: =IF(A58=1,0,ROUND(cost_workshop_bone*1*cost_growth^(A58-2)*IF(A58<=4,stage_early,IF(A58<=stage_mid_level,stage_mid,IF(A58<=stage_late_level,stage_normal,stage_late))),0)) -> 20877 | I58: =IF(A58=1,0,ROUND(build_time_base_min*time_coef_workshop*time_growth^(A58-2)*IF(A58<=4,stage_early,IF(A58<=stage_mid_level,stage_mid,IF(A58<=stage_late_level,stage_normal,stage_late)))/60,1)) -> 42.4
A59: 3. RAZVEDKA QOYASI — 🔍 razvedkachi tieri
A60: Daraja | B60: Ochadigan tier | C60: Askar sigʻimi | D60: Mashq tezligi | E60: Narx: tosh | F60: Narx: suyak | G60: Narx: teri | H60: Qurilish vaqti (soat)
A61: 1 | B61: =MAX(1,MIN(6,INT(A61/tier_step_building))) -> 1 | C61: =ROUND(role_cap_base*role_cap_growth^(A61-1),0) -> 6 | D61: =1+train_speed_per_level*(A61-1) -> 1 | E61: =IF(A61=1,0,ROUND(cost_role_stone*cost_coef_scout_rock*cost_growth^(A61-2)*IF(A61<=4,stage_early,IF(A61<=stage_mid_level,stage_mid,IF(A61<=stage_late_level,stage_normal,stage_late))),0)) -> 0 | F61: =IF(A61=1,0,ROUND(cost_role_bone*cost_coef_scout_rock*cost_growth^(A61-2)*IF(A61<=4,stage_early,IF(A61<=stage_mid_level,stage_mid,IF(A61<=stage_late_level,stage_normal,stage_late))),0)) -> 0 | G61: =IF(A61=1,0,ROUND(cost_role_hide*cost_coef_scout_rock*cost_growth^(A61-2)*IF(A61<=4,stage_early,IF(A61<=stage_mid_level,stage_mid,IF(A61<=stage_late_level,stage_normal,stage_late))),0)) -> 0 | H61: =IF(A61=1,0,ROUND(build_time_base_min*time_coef_scout_rock*time_growth^(A61-2)*IF(A61<=4,stage_early,IF(A61<=stage_mid_level,stage_mid,IF(A61<=stage_late_level,stage_normal,stage_late)))/60,1)) -> 0
A62: 2 | B62: =MAX(1,MIN(6,INT(A62/tier_step_building))) -> 1 | C62: =ROUND(role_cap_base*role_cap_growth^(A62-1),0) -> 7 | D62: =1+train_speed_per_level*(A62-1) -> 1.04 | E62: =IF(A62=1,0,ROUND(cost_role_stone*cost_coef_scout_rock*cost_growth^(A62-2)*IF(A62<=4,stage_early,IF(A62<=stage_mid_level,stage_mid,IF(A62<=stage_late_level,stage_normal,stage_late))),0)) -> 36 | F62: =IF(A62=1,0,ROUND(cost_role_bone*cost_coef_scout_rock*cost_growth^(A62-2)*IF(A62<=4,stage_early,IF(A62<=stage_mid_level,stage_mid,IF(A62<=stage_late_level,stage_normal,stage_late))),0)) -> 18 | G62: =IF(A62=1,0,ROUND(cost_role_hide*cost_coef_scout_rock*cost_growth^(A62-2)*IF(A62<=4,stage_early,IF(A62<=stage_mid_level,stage_mid,IF(A62<=stage_late_level,stage_normal,stage_late))),0)) -> 30 | H62: =IF(A62=1,0,ROUND(build_time_base_min*time_coef_scout_rock*time_growth^(A62-2)*IF(A62<=4,stage_early,IF(A62<=stage_mid_level,stage_mid,IF(A62<=stage_late_level,stage_normal,stage_late)))/60,1)) -> 0.1
A63: 3 | B63: =MAX(1,MIN(6,INT(A63/tier_step_building))) -> 1 | C63: =ROUND(role_cap_base*role_cap_growth^(A63-1),0) -> 9 | D63: =1+train_speed_per_level*(A63-1) -> 1.08 | E63: =IF(A63=1,0,ROUND(cost_role_stone*cost_coef_scout_rock*cost_growth^(A63-2)*IF(A63<=4,stage_early,IF(A63<=stage_mid_level,stage_mid,IF(A63<=stage_late_level,stage_normal,stage_late))),0)) -> 47 | F63: =IF(A63=1,0,ROUND(cost_role_bone*cost_coef_scout_rock*cost_growth^(A63-2)*IF(A63<=4,stage_early,IF(A63<=stage_mid_level,stage_mid,IF(A63<=stage_late_level,stage_normal,stage_late))),0)) -> 23 | G63: =IF(A63=1,0,ROUND(cost_role_hide*cost_coef_scout_rock*cost_growth^(A63-2)*IF(A63<=4,stage_early,IF(A63<=stage_mid_level,stage_mid,IF(A63<=stage_late_level,stage_normal,stage_late))),0)) -> 39 | H63: =IF(A63=1,0,ROUND(build_time_base_min*time_coef_scout_rock*time_growth^(A63-2)*IF(A63<=4,stage_early,IF(A63<=stage_mid_level,stage_mid,IF(A63<=stage_late_level,stage_normal,stage_late)))/60,1)) -> 0.1
A64: 4 | B64: =MAX(1,MIN(6,INT(A64/tier_step_building))) -> 1 | C64: =ROUND(role_cap_base*role_cap_growth^(A64-1),0) -> 10 | D64: =1+train_speed_per_level*(A64-1) -> 1.12 | E64: =IF(A64=1,0,ROUND(cost_role_stone*cost_coef_scout_rock*cost_growth^(A64-2)*IF(A64<=4,stage_early,IF(A64<=stage_mid_level,stage_mid,IF(A64<=stage_late_level,stage_normal,stage_late))),0)) -> 61 | F64: =IF(A64=1,0,ROUND(cost_role_bone*cost_coef_scout_rock*cost_growth^(A64-2)*IF(A64<=4,stage_early,IF(A64<=stage_mid_level,stage_mid,IF(A64<=stage_late_level,stage_normal,stage_late))),0)) -> 30 | G64: =IF(A64=1,0,ROUND(cost_role_hide*cost_coef_scout_rock*cost_growth^(A64-2)*IF(A64<=4,stage_early,IF(A64<=stage_mid_level,stage_mid,IF(A64<=stage_late_level,stage_normal,stage_late))),0)) -> 51 | H64: =IF(A64=1,0,ROUND(build_time_base_min*time_coef_scout_rock*time_growth^(A64-2)*IF(A64<=4,stage_early,IF(A64<=stage_mid_level,stage_mid,IF(A64<=stage_late_level,stage_normal,stage_late)))/60,1)) -> 0.1
A65: 5 | B65: =MAX(1,MIN(6,INT(A65/tier_step_building))) -> 1 | C65: =ROUND(role_cap_base*role_cap_growth^(A65-1),0) -> 12 | D65: =1+train_speed_per_level*(A65-1) -> 1.16 | E65: =IF(A65=1,0,ROUND(cost_role_stone*cost_coef_scout_rock*cost_growth^(A65-2)*IF(A65<=4,stage_early,IF(A65<=stage_mid_level,stage_mid,IF(A65<=stage_late_level,stage_normal,stage_late))),0)) -> 138 | F65: =IF(A65=1,0,ROUND(cost_role_bone*cost_coef_scout_rock*cost_growth^(A65-2)*IF(A65<=4,stage_early,IF(A65<=stage_mid_level,stage_mid,IF(A65<=stage_late_level,stage_normal,stage_late))),0)) -> 69 | G65: =IF(A65=1,0,ROUND(cost_role_hide*cost_coef_scout_rock*cost_growth^(A65-2)*IF(A65<=4,stage_early,IF(A65<=stage_mid_level,stage_mid,IF(A65<=stage_late_level,stage_normal,stage_late))),0)) -> 115 | H65: =IF(A65=1,0,ROUND(build_time_base_min*time_coef_scout_rock*time_growth^(A65-2)*IF(A65<=4,stage_early,IF(A65<=stage_mid_level,stage_mid,IF(A65<=stage_late_level,stage_normal,stage_late)))/60,1)) -> 0.2
A66: 6 | B66: =MAX(1,MIN(6,INT(A66/tier_step_building))) -> 1 | C66: =ROUND(role_cap_base*role_cap_growth^(A66-1),0) -> 15 | D66: =1+train_speed_per_level*(A66-1) -> 1.2 | E66: =IF(A66=1,0,ROUND(cost_role_stone*cost_coef_scout_rock*cost_growth^(A66-2)*IF(A66<=4,stage_early,IF(A66<=stage_mid_level,stage_mid,IF(A66<=stage_late_level,stage_normal,stage_late))),0)) -> 180 | F66: =IF(A66=1,0,ROUND(cost_role_bone*cost_coef_scout_rock*cost_growth^(A66-2)*IF(A66<=4,stage_early,IF(A66<=stage_mid_level,stage_mid,IF(A66<=stage_late_level,stage_normal,stage_late))),0)) -> 90 | G66: =IF(A66=1,0,ROUND(cost_role_hide*cost_coef_scout_rock*cost_growth^(A66-2)*IF(A66<=4,stage_early,IF(A66<=stage_mid_level,stage_mid,IF(A66<=stage_late_level,stage_normal,stage_late))),0)) -> 150 | H66: =IF(A66=1,0,ROUND(build_time_base_min*time_coef_scout_rock*time_growth^(A66-2)*IF(A66<=4,stage_early,IF(A66<=stage_mid_level,stage_mid,IF(A66<=stage_late_level,stage_normal,stage_late)))/60,1)) -> 0.2
...

Sheet Umumiy bogʻlanish
A3: Umumiy bogʻlanish — daraja, jang, oziq va binolar bir jadvalda
A4: Boshqa varaqlardan formulalar orqali yigʻiladi — Sozlamalar oʻzgarsa shu jadval ham oʻzgaradi.
A5: Daraja | B5: Boʻri nomi | C5: Toifa | D5: Jami XP | E5: Jangovar quvvat | F5: Toʻda hajmi | G5: Goʻsht (kg/kun) | H5: Ov soni (kun) | I5: Suv (kun) | J5: Oy nuri (kun) | K5: Kerakli Oziq gʻori | L5: Kunlik qurilish resursi | M5: Kerakli Ustaxona | N5: Kunlik ov (4 ov, kg) | O5: Bosqich | P5: Ochiladigan imkoniyat | Q5: Maks. tier | R5: 🔍 Razvedkachi | S5: ⚔️ Hujumchi | T5: 🛡 Himoyachi | U5: 🥩 Ovchi | V5: Kerakli rol binosi | W5: Toʻda jangovar quvvati | X5: 1-darajaga nisbatan
A6: 1 | B6: =Darajalar!B6 -> Honsyu boʻrisi | C6: =Darajalar!D6 -> Haqiqiy | D6: =Darajalar!J6 -> 0 | E6: =Darajalar!N6 -> 69 | F6: =Darajalar!O6 -> 1 | G6: =Oziqlanish!E6 -> 1 | H6: =Oziqlanish!J6 -> 2 | I6: =Oziqlanish!F6 -> 0 | J6: =Oziqlanish!G6 -> 0 | K6: =Oziqlanish!L6 -> 1 | L6: =ROUND((INDEX(Binolar!$F$7:$F$31,MIN(25,K6+1))+INDEX(Binolar!$G$7:$G$31,MIN(25,K6+1)))/build_plan_days,0) -> 9 | M6: =COUNTIF(Binolar!$C$34:$C$58,"<"&L6)+1 -> 1 | N6: =ROUND(4*'Askar iqtisodi'!F24*hunter_yield_mult*Oziqlanish!C6*hunt_duration_min/60,0) -> 12 | O6: =IF(C6="Haqiqiy","Asosiy oʻyin",IF(C6="Qadimgi","Qadimgi bosqich","Afsona bosqichi")) -> Asosiy oʻyin | P6: Yolgʻiz ov (alfa): kemiruvchi va qush; In | Q6: ='Askar iqtisodi'!G24 -> 1 | R6: ='Askar iqtisodi'!C24 -> 0 | S6: ='Askar iqtisodi'!D24 -> 0 | T6: ='Askar iqtisodi'!E24 -> 0 | U6: ='Askar iqtisodi'!F24 -> 1 | V6: =IF(Q6<=1,1,Q6*tier_step_building) -> 1 | W6: =ROUND((R6*(Rollar!$E$7*cp_w_power+Rollar!$F$7*cp_w_speed+Rollar!$G$7*cp_w_hp)+S6*(Rollar!$E$8*cp_w_power+Rollar!$F$8*cp_w_speed+Rollar!$G$8*cp_w_hp)+T6*(Rollar!$E$9*cp_w_power+Rollar!$F$9*cp_w_speed+Rollar!$G$9*cp_w_hp)+U6*(Rollar!$E$10*cp_w_power+Rollar!$F$10*cp_w_speed+Rollar!$G$10*cp_w_hp))*tier_coef^(Q6-1)*(1+alpha_bonus*A6),0) -> 63 | X6: =ROUND(W6/$W$6,1) -> 1
A7: 2 | B7: =Darajalar!B7 -> Efiopiya boʻrisi | C7: =Darajalar!D7 -> Haqiqiy | D7: =Darajalar!J7 -> 30 | E7: =Darajalar!N7 -> 81 | F7: =Darajalar!O7 -> 1 | G7: =Oziqlanish!E7 -> 1 | H7: =Oziqlanish!J7 -> 1 | I7: =Oziqlanish!F7 -> 0 | J7: =Oziqlanish!G7 -> 0 | K7: =Oziqlanish!L7 -> 1 | L7: =ROUND((INDEX(Binolar!$F$7:$F$31,MIN(25,K7+1))+INDEX(Binolar!$G$7:$G$31,MIN(25,K7+1)))/build_plan_days,0) -> 9 | M7: =COUNTIF(Binolar!$C$34:$C$58,"<"&L7)+1 -> 1 | N7: =ROUND(4*'Askar iqtisodi'!F25*hunter_yield_mult*Oziqlanish!C7*hunt_duration_min/60,0) -> 14 | O7: =IF(C7="Haqiqiy","Asosiy oʻyin",IF(C7="Qadimgi","Qadimgi bosqich","Afsona bosqichi")) -> Asosiy oʻyin | P7: Oziq gʻori va Ustaxona qoyasi | Q7: ='Askar iqtisodi'!G25 -> 1 | R7: ='Askar iqtisodi'!C25 -> 0 | S7: ='Askar iqtisodi'!D25 -> 0 | T7: ='Askar iqtisodi'!E25 -> 0 | U7: ='Askar iqtisodi'!F25 -> 1 | V7: =IF(Q7<=1,1,Q7*tier_step_building) -> 1 | W7: =ROUND((R7*(Rollar!$E$7*cp_w_power+Rollar!$F$7*cp_w_speed+Rollar!$G$7*cp_w_hp)+S7*(Rollar!$E$8*cp_w_power+Rollar!$F$8*cp_w_speed+Rollar!$G$8*cp_w_hp)+T7*(Rollar!$E$9*cp_w_power+Rollar!$F$9*cp_w_speed+Rollar!$G$9*cp_w_hp)+U7*(Rollar!$E$10*cp_w_power+Rollar!$F$10*cp_w_speed+Rollar!$G$10*cp_w_hp))*tier_coef^(Q7-1)*(1+alpha_bonus*A7),0) -> 65 | X7: =ROUND(W7/$W$6,1) -> 1
A8: 3 | B8: =Darajalar!B8 -> Arab boʻrisi | C8: =Darajalar!D8 -> Haqiqiy | D8: =Darajalar!J8 -> 70 | E8: =Darajalar!N8 -> 97 | F8: =Darajalar!O8 -> 1 | G8: =Oziqlanish!E8 -> 1 | H8: =Oziqlanish!J8 -> 1 | I8: =Oziqlanish!F8 -> 0 | J8: =Oziqlanish!G8 -> 0 | K8: =Oziqlanish!L8 -> 1 | L8: =ROUND((INDEX(Binolar!$F$7:$F$31,MIN(25,K8+1))+INDEX(Binolar!$G$7:$G$31,MIN(25,K8+1)))/build_plan_days,0) -> 9 | M8: =COUNTIF(Binolar!$C$34:$C$58,"<"&L8)+1 -> 1 | N8: =ROUND(4*'Askar iqtisodi'!F26*hunter_yield_mult*Oziqlanish!C8*hunt_duration_min/60,0) -> 16 | O8: =IF(C8="Haqiqiy","Asosiy oʻyin",IF(C8="Qadimgi","Qadimgi bosqich","Afsona bosqichi")) -> Asosiy oʻyin | P8: Ov soʻqmogʻi, birinchi ovchi, quyon ovi | Q8: ='Askar iqtisodi'!G26 -> 1 | R8: ='Askar iqtisodi'!C26 -> 0 | S8: ='Askar iqtisodi'!D26 -> 0 | T8: ='Askar iqtisodi'!E26 -> 0 | U8: ='Askar iqtisodi'!F26 -> 1 | V8: =IF(Q8<=1,1,Q8*tier_step_building) -> 1 | W8: =ROUND((R8*(Rollar!$E$7*cp_w_power+Rollar!$F$7*cp_w_speed+Rollar!$G$7*cp_w_hp)+S8*(Rollar!$E$8*cp_w_power+Rollar!$F$8*cp_w_speed+Rollar!$G$8*cp_w_hp)+T8*(Rollar!$E$9*cp_w_power+Rollar!$F$9*cp_w_speed+Rollar!$G$9*cp_w_hp)+U8*(Rollar!$E$10*cp_w_power+Rollar!$F$10*cp_w_speed+Rollar!$G$10*cp_w_hp))*tier_coef^(Q8-1)*(1+alpha_bonus*A8),0) -> 66 | X8: =ROUND(W8/$W$6,1) -> 1
A9: 4 | B9: =Darajalar!B9 -> Hind boʻrisi | C9: =Darajalar!D9 -> Haqiqiy | D9: =Darajalar!J9 -> 130 | E9: =Darajalar!N9 -> 114 | F9: =Darajalar!O9 -> 10 | G9: =Oziqlanish!E9 -> 9 | H9: =Oziqlanish!J9 -> 2 | I9: =Oziqlanish!F9 -> 5 | J9: =Oziqlanish!G9 -> 0 | K9: =Oziqlanish!L9 -> 1 | L9: =ROUND((INDEX(Binolar!$F$7:$F$31,MIN(25,K9+1))+INDEX(Binolar!$G$7:$G$31,MIN(25,K9+1)))/build_plan_days,0) -> 9 | M9: =COUNTIF(Binolar!$C$34:$C$58,"<"&L9)+1 -> 1 | N9: =ROUND(4*'Askar iqtisodi'!F27*hunter_yield_mult*Oziqlanish!C9*hunt_duration_min/60,0) -> 36 | O9: =IF(C9="Haqiqiy","Asosiy oʻyin",IF(C9="Qadimgi","Qadimgi bosqich","Afsona bosqichi")) -> Asosiy oʻyin | P9: 🔓 TOʻDA: qoʻshin 10 askar · Jang maydoni, Razvedka qoyasi, Himoya devori · yovvoyi toʻdalarga (bot) hujum · ov guruhi · klan va lager (v2) | Q9: ='Askar iqtisodi'!G27 -> 1 | R9: ='Askar iqtisodi'!C27 -> 2 | S9: ='Askar iqtisodi'!D27 -> 4 | T9: ='Askar iqtisodi'!E27 -> 2 | U9: ='Askar iqtisodi'!F27 -> 2 | V9: =IF(Q9<=1,1,Q9*tier_step_building) -> 1 | W9: =ROUND((R9*(Rollar!$E$7*cp_w_power+Rollar!$F$7*cp_w_speed+Rollar!$G$7*cp_w_hp)+S9*(Rollar!$E$8*cp_w_power+Rollar!$F$8*cp_w_speed+Rollar!$G$8*cp_w_hp)+T9*(Rollar!$E$9*cp_w_power+Rollar!$F$9*cp_w_speed+Rollar!$G$9*cp_w_hp)+U9*(Rollar!$E$10*cp_w_power+Rollar!$F$10*cp_w_speed+Rollar!$G$10*cp_w_hp))*tier_coef^(Q9-1)*(1+alpha_bonus*A9),0) -> 822 | X9: =ROUND(W9/$W$6,1) -> 13
A10: 5 | B10: =Darajalar!B10 -> Qizil boʻri | C10: =Darajalar!D10 -> Haqiqiy | D10: =Darajalar!J10 -> 280 | E10: =Darajalar!N10 -> 135 | F10: =Darajalar!O10 -> 12 | G10: =Oziqlanish!E10 -> 12 | H10: =Oziqlanish!J10 -> 1 | I10: =Oziqlanish!F10 -> 7 | J10: =Oziqlanish!G10 -> 0 | K10: =Oziqlanish!L10 -> 1 | L10: =ROUND((INDEX(Binolar!$F$7:$F$31,MIN(25,K10+1))+INDEX(Binolar!$G$7:$G$31,MIN(25,K10+1)))/build_plan_days,0) -> 9 | M10: =COUNTIF(Binolar!$C$34:$C$58,"<"&L10)+1 -> 1 | N10: =ROUND(4*'Askar iqtisodi'!F28*hunter_yield_mult*Oziqlanish!C10*hunt_duration_min/60,0) -> 40 | O10: =IF(C10="Haqiqiy","Asosiy oʻyin",IF(C10="Qadimgi","Qadimgi bosqich","Afsona bosqichi")) -> Asosiy oʻyin | P10: Yirik oʻlja — jayron (kamida 2 boʻri) | Q10: ='Askar iqtisodi'!G28 -> 1 | R10: ='Askar iqtisodi'!C28 -> 2 | S10: ='Askar iqtisodi'!D28 -> 6 | T10: ='Askar iqtisodi'!E28 -> 2 | U10: ='Askar iqtisodi'!F28 -> 2 | V10: =IF(Q10<=1,1,Q10*tier_step_building) -> 1 | W10: =ROUND((R10*(Rollar!$E$7*cp_w_power+Rollar!$F$7*cp_w_speed+Rollar!$G$7*cp_w_hp)+S10*(Rollar!$E$8*cp_w_power+Rollar!$F$8*cp_w_speed+Rollar!$G$8*cp_w_hp)+T10*(Rollar!$E$9*cp_w_power+Rollar!$F$9*cp_w_speed+Rollar!$G$9*cp_w_hp)+U10*(Rollar!$E$10*cp_w_power+Rollar!$F$10*cp_w_speed+Rollar!$G$10*cp_w_hp))*tier_coef^(Q10-1)*(1+alpha_bonus*A10),0) -> 1029 | X10: =ROUND(W10/$W$6,1) -> 16.3
